Workbook

Sheet DASHBOARD
A1: 📊 CRM DASHBOARD - ЦЕНТР УПРАВЛЕНИЯ ПРОДАЖАМИ
A3: 📈 КЛЮЧЕВЫЕ ПОКАЗАТЕЛИ - ОБЩАЯ СТАТИСТИКА
B5: ЛИДЫ | E5: НЕ ДОЗВОН | H5: ОЖИДАНИЕ | K5: ОТКАЗ | N5: 🎯 ПРОДАЖИ
B6: =SUM(B18:B37) | E6: =SUM(D18:D37) | H6: =SUM(E18:E37) | K6: =SUM(F18:F37) | N6: =SUM(G18:G37)
A10: 💰 ВЫРУЧКА | E10: 📊 КОНВЕРСИЯ | I10: 💵 СРЕДНИЙ ЧЕК | M10: 💰 ОБЩИЙ ОСТАТОК
A11: =SUM(I18:I37) | E11: =IF(B6=0,0,N6/B6*100) | I11: =IF(N6=0,0,A11/N6) | M11: =SUM(K18:K37)
A16: 👥 СВОДНАЯ СТАТИСТИКА ПО МЕНЕДЖЕРАМ
A17: Менеджер | B17: Лиды | C17: Обработка | D17: Не дозвон | E17: Ожидание | F17: Отказ | G17: Продажи | H17: Конверсия | I17: Выручка | J17: Ср. чек | K17: Остаток | L17: Рейтинг
A18: Менеджер 1 | B18: =Mgr_1!AG4 | C18: =Mgr_1!AG5 | D18: =Mgr_1!AG6 | E18: =Mgr_1!AG7 | F18: =Mgr_1!AG8 | G18: =Mgr_1!AG9 | H18: =Mgr_1!AG11 | I18: =Mgr_1!AG10 | J18: =IF(G18=0,0,I18/G18) | K18: =Mgr_1!AG12 | L18: =RANK(I18,I$18:I$37,0)
A19: Менеджер 2 | B19: =Mgr_2!AG4 | C19: =Mgr_2!AG5 | D19: =Mgr_2!AG6 | E19: =Mgr_2!AG7 | F19: =Mgr_2!AG8 | G19: =Mgr_2!AG9 | H19: =Mgr_2!AG11 | I19: =Mgr_2!AG10 | J19: =IF(G19=0,0,I19/G19) | K19: =Mgr_2!AG12 | L19: =RANK(I19,I$18:I$37,0)
A20: Менеджер 3 | B20: =Mgr_3!AG4 | C20: =Mgr_3!AG5 | D20: =Mgr_3!AG6 | E20: =Mgr_3!AG7 | F20: =Mgr_3!AG8 | G20: =Mgr_3!AG9 | H20: =Mgr_3!AG11 | I20: =Mgr_3!AG10 | J20: =IF(G20=0,0,I20/G20) | K20: =Mgr_3!AG12 | L20: =RANK(I20,I$18:I$37,0)
A21: Менеджер 4 | B21: =Mgr_4!AG4 | C21: =Mgr_4!AG5 | D21: =Mgr_4!AG6 | E21: =Mgr_4!AG7 | F21: =Mgr_4!AG8 | G21: =Mgr_4!AG9 | H21: =Mgr_4!AG11 | I21: =Mgr_4!AG10 | J21: =IF(G21=0,0,I21/G21) | K21: =Mgr_4!AG12 | L21: =RANK(I21,I$18:I$37,0)
A22: Менеджер 5 | B22: =Mgr_5!AG4 | C22: =Mgr_5!AG5 | D22: =Mgr_5!AG6 | E22: =Mgr_5!AG7 | F22: =Mgr_5!AG8 | G22: =Mgr_5!AG9 | H22: =Mgr_5!AG11 | I22: =Mgr_5!AG10 | J22: =IF(G22=0,0,I22/G22) | K22: =Mgr_5!AG12 | L22: =RANK(I22,I$18:I$37,0)
A23: Менеджер 6 | B23: =Mgr_6!AG4 | C23: =Mgr_6!AG5 | D23: =Mgr_6!AG6 | E23: =Mgr_6!AG7 | F23: =Mgr_6!AG8 | G23: =Mgr_6!AG9 | H23: =Mgr_6!AG11 | I23: =Mgr_6!AG10 | J23: =IF(G23=0,0,I23/G23) | K23: =Mgr_6!AG12 | L23: =RANK(I23,I$18:I$37,0)
A24: Менеджер 7 | B24: =Mgr_7!AG4 | C24: =Mgr_7!AG5 | D24: =Mgr_7!AG6 | E24: =Mgr_7!AG7 | F24: =Mgr_7!AG8 | G24: =Mgr_7!AG9 | H24: =Mgr_7!AG11 | I24: =Mgr_7!AG10 | J24: =IF(G24=0,0,I24/G24) | K24: =Mgr_7!AG12 | L24: =RANK(I24,I$18:I$37,0)
A25: Менеджер 8 | B25: =Mgr_8!AG4 | C25: =Mgr_8!AG5 | D25: =Mgr_8!AG6 | E25: =Mgr_8!AG7 | F25: =Mgr_8!AG8 | G25: =Mgr_8!AG9 | H25: =Mgr_8!AG11 | I25: =Mgr_8!AG10 | J25: =IF(G25=0,0,I25/G25) | K25: =Mgr_8!AG12 | L25: =RANK(I25,I$18:I$37,0)
A26: Менеджер 9 | B26: =Mgr_9!AG4 | C26: =Mgr_9!AG5 | D26: =Mgr_9!AG6 | E26: =Mgr_9!AG7 | F26: =Mgr_9!AG8 | G26: =Mgr_9!AG9 | H26: =Mgr_9!AG11 | I26: =Mgr_9!AG10 | J26: =IF(G26=0,0,I26/G26) | K26: =Mgr_9!AG12 | L26: =RANK(I26,I$18:I$37,0)
A27: Менеджер 10 | B27: =Mgr_10!AG4 | C27: =Mgr_10!AG5 | D27: =Mgr_10!AG6 | E27: =Mgr_10!AG7 | F27: =Mgr_10!AG8 | G27: =Mgr_10!AG9 | H27: =Mgr_10!AG11 | I27: =Mgr_10!AG10 | J27: =IF(G27=0,0,I27/G27) | K27: =Mgr_10!AG12 | L27: =RANK(I27,I$18:I$37,0)
A28: Менеджер 11 | B28: =Mgr_11!AG4 | C28: =Mgr_11!AG5 | D28: =Mgr_11!AG6 | E28: =Mgr_11!AG7 | F28: =Mgr_11!AG8 | G28: =Mgr_11!AG9 | H28: =Mgr_11!AG11 | I28: =Mgr_11!AG10 | J28: =IF(G28=0,0,I28/G28) | K28: =Mgr_11!AG12 | L28: =RANK(I28,I$18:I$37,0)
A29: Менеджер 12 | B29: =Mgr_12!AG4 | C29: =Mgr_12!AG5 | D29: =Mgr_12!AG6 | E29: =Mgr_12!AG7 | F29: =Mgr_12!AG8 | G29: =Mgr_12!AG9 | H29: =Mgr_12!AG11 | I29: =Mgr_12!AG10 | J29: =IF(G29=0,0,I29/G29) | K29: =Mgr_12!AG12 | L29: =RANK(I29,I$18:I$37,0)
A30: Менеджер 13 | B30: =Mgr_13!AG4 | C30: =Mgr_13!AG5 | D30: =Mgr_13!AG6 | E30: =Mgr_13!AG7 | F30: =Mgr_13!AG8 | G30: =Mgr_13!AG9 | H30: =Mgr_13!AG11 | I30: =Mgr_13!AG10 | J30: =IF(G30=0,0,I30/G30) | K30: =Mgr_13!AG12 | L30: =RANK(I30,I$18:I$37,0)
A31: Менеджер 14 | B31: =Mgr_14!AG4 | C31: =Mgr_14!AG5 | D31: =Mgr_14!AG6 | E31: =Mgr_14!AG7 | F31: =Mgr_14!AG8 | G31: =Mgr_14!AG9 | H31: =Mgr_14!AG11 | I31: =Mgr_14!AG10 | J31: =IF(G31=0,0,I31/G31) | K31: =Mgr_14!AG12 | L31: =RANK(I31,I$18:I$37,0)
A32: Менеджер 15 | B32: =Mgr_15!AG4 | C32: =Mgr_15!AG5 | D32: =Mgr_15!AG6 | E32: =Mgr_15!AG7 | F32: =Mgr_15!AG8 | G32: =Mgr_15!AG9 | H32: =Mgr_15!AG11 | I32: =Mgr_15!AG10 | J32: =IF(G32=0,0,I32/G32) | K32: =Mgr_15!AG12 | L32: =RANK(I32,I$18:I$37,0)
A33: Менеджер 16 | B33: =Mgr_16!AG4 | C33: =Mgr_16!AG5 | D33: =Mgr_16!AG6 | E33: =Mgr_16!AG7 | F33: =Mgr_16!AG8 | G33: =Mgr_16!AG9 | H33: =Mgr_16!AG11 | I33: =Mgr_16!AG10 | J33: =IF(G33=0,0,I33/G33) | K33: =Mgr_16!AG12 | L33: =RANK(I33,I$18:I$37,0)
A34: Менеджер 17 | B34: =Mgr_17!AG4 | C34: =Mgr_17!AG5 | D34: =Mgr_17!AG6 | E34: =Mgr_17!AG7 | F34: =Mgr_17!AG8 | G34: =Mgr_17!AG9 | H34: =Mgr_17!AG11 | I34: =Mgr_17!AG10 | J34: =IF(G34=0,0,I34/G34) | K34: =Mgr_17!AG12 | L34: =RANK(I34,I$18:I$37,0)
A35: Менеджер 18 | B35: =Mgr_18!AG4 | C35: =Mgr_18!AG5 | D35: =Mgr_18!AG6 | E35: =Mgr_18!AG7 | F35: =Mgr_18!AG8 | G35: =Mgr_18!AG9 | H35: =Mgr_18!AG11 | I35: =Mgr_18!AG10 | J35: =IF(G35=0,0,I35/G35) | K35: =Mgr_18!AG12 | L35: =RANK(I35,I$18:I$37,0)
A36: Менеджер 19 | B36: =Mgr_19!AG4 | C36: =Mgr_19!AG5 | D36: =Mgr_19!AG6 | E36: =Mgr_19!AG7 | F36: =Mgr_19!AG8 | G36: =Mgr_19!AG9 | H36: =Mgr_19!AG11 | I36: =Mgr_19!AG10 | J36: =IF(G36=0,0,I36/G36) | K36: =Mgr_19!AG12 | L36: =RANK(I36,I$18:I$37,0)
A37: Менеджер 20 | B37: =Mgr_20!AG4 | C37: =Mgr_20!AG5 | D37: =Mgr_20!AG6 | E37: =Mgr_20!AG7 | F37: =Mgr_20!AG8 | G37: =Mgr_20!AG9 | H37: =Mgr_20!AG11 | I37: =Mgr_20!AG10 | J37: =IF(G37=0,0,I37/G37) | K37: =Mgr_20!AG12 | L37: =RANK(I37,I$18:I$37,0)
A38: ИТОГО | B38: =SUM(B18:B37) | C38: =SUM(C18:C37) | D38: =SUM(D18:D37) | E38: =SUM(E18:E37) | F38: =SUM(F18:F37) | G38: =SUM(G18:G37) | H38: =IF(B38=0,0,G38/B38*100) | I38: =SUM(I18:I37) | J38: =IF(G38=0,0,I38/G38) | K38: =SUM(K18:K37) | L38: -
A41: 🏆 РЕЙТИНГ ПРОДАВЦОВ
B43: 📅 ПО ДНЯМ ▼ | F43: 📆 ПО НЕДЕЛЯМ | J43: 📊 ПО МЕСЯЦАМ
A45: 📅 РЕЙТИНГ ПО ДНЯМ МЕСЯЦА (ВЫРУЧКА)
A46: Менеджер | B46: 02 | C46: 03 | D46: 04 | E46: 05 | F46: 06 | G46: 07 | H46: 08 | I46: 09 | J46: 10 | K46: 11 | L46: 12 | M46: 13 | N46: 14 | O46: 15 | P46: 16 | Q46: 17 | R46: 17 | S46: 18 | T46: 19 | U46: 20 | V46: 21 | W46: 22 | X46: 23 | Y46: 24 | Z46: 25 | AA46: 26 | AB46: 27 | AC46: 28 | AD46: 29 | AE46: 30 | AF46: 31
A47: Менеджер 1 | B47: =Mgr_1!B10 | C47: =Mgr_1!C10 | D47: =Mgr_1!D10 | E47: =Mgr_1!E10 | F47: =Mgr_1!F10 | G47: =Mgr_1!G10 | H47: =Mgr_1!H10 | I47: =Mgr_1!I10 | ... AF47: =Mgr_1!AF10
A48: Менеджер 2 | B48: =Mgr_2!B10 | C48: =Mgr_2!C10 | D48: =Mgr_2!D10 | E48: =Mgr_2!E10 | F48: =Mgr_2!F10 | G48: =Mgr_2!G10 | H48: =Mgr_2!H10 | I48: =Mgr_2!I10 | ... AF48: =Mgr_2!AF10
A49: Менеджер 3 | B49: =Mgr_3!B10 | C49: =Mgr_3!C10 | D49: =Mgr_3!D10 | E49: =Mgr_3!E10 | F49: =Mgr_3!F10 | G49: =Mgr_3!G10 | H49: =Mgr_3!H10 | I49: =Mgr_3!I10 | ... AF49: =Mgr_3!AF10
A50: Менеджер 4 | B50: =Mgr_4!B10 | C50: =Mgr_4!C10 | D50: =Mgr_4!D10 | E50: =Mgr_4!E10 | F50: =Mgr_4!F10 | G50: =Mgr_4!G10 | H50: =Mgr_4!H10 | I50: =Mgr_4!I10 | ... AF50: =Mgr_4!AF10
A51: Менеджер 5 | B51: =Mgr_5!B10 | C51: =Mgr_5!C10 | D51: =Mgr_5!D10 | E51: =Mgr_5!E10 | F51: =Mgr_5!F10 | G51: =Mgr_5!G10 | H51: =Mgr_5!H10 | I51: =Mgr_5!I10 | ... AF51: =Mgr_5!AF10
A52: Менеджер 6 | B52: =Mgr_6!B10 | C52: =Mgr_6!C10 | D52: =Mgr_6!D10 | E52: =Mgr_6!E10 | F52: =Mgr_6!F10 | G52: =Mgr_6!G10 | H52: =Mgr_6!H10 | I52: =Mgr_6!I10 | ... AF52: =Mgr_6!AF10
A53: Менеджер 7 | B53: =Mgr_7!B10 | C53: =Mgr_7!C10 | D53: =Mgr_7!D10 | E53: =Mgr_7!E10 | F53: =Mgr_7!F10 | G53: =Mgr_7!G10 | H53: =Mgr_7!H10 | I53: =Mgr_7!I10 | ... AF53: =Mgr_7!AF10
...

Sheet Mgr_1
A1: 📈 ЕЖЕДНЕВНЫЙ ОТЧЕТ - МЕНЕДЖЕР 1
A2: ПОКАЗАТЕЛИ ЭФФЕКТИВНОСТИ ПО ДНЯМ МЕСЯЦА
A3: МЕТРИКА / ДАТА | B3: 01 | C3: 02 | D3: 03 | E3: 04 | F3: 05 | G3: 06 | H3: 07 | I3: 08 | J3: 09 | K3: 10 | L3: 11 | M3: 12 | N3: 13 | O3: 14 | P3: 15 | Q3: 16 | R3: 17 | S3: 18 | T3: 19 | U3: 20 | V3: 21 | W3: 22 | X3: 23 | Y3: 24 | Z3: 25 | AA3: 26 | AB3: 27 | AC3: 28 | AD3: 29 | AE3: 30 | AF3: 31 | AG3: ИТОГО
A4: Лиды | N4: 10 | O4: 10 | AG4: =SUM(B4:AF4)
A5: Обработка | N5: 1 | AG5: =SUM(B5:AF5)
A6: Не дозвон | N6: 1 | O6: 10 | AG6: =SUM(B6:AF6)
A7: Ожидание | O7: 10 | AG7: =SUM(B7:AF7)
A8: Отказ | N8: 3 | AG8: =SUM(B8:AF8)
A9: Продажа | N9: 1 | O9: 4 | AG9: =SUM(B9:AF9)
A10: Выручка (сом) | N10: 40000 | O10: 10000 | AG10: =SUM(B10:AF10)
A11: Конверсия % | AG11: =IF(AG4=0,0,AG9/AG4*100)
A12: Остаток (сом) | AG12: =SUM(B12:AF12)
A14: 💡 ИНСТРУКЦИЯ: Заполняйте ежедневный отчет вручную (строки 4-12). В таблице клиентов выбирайте "Статус оплаты" из списка. Остаток рассчитывается автоматически.
A15: 📋 РЕЕСТР КЛИЕНТОВ - МЕНЕДЖЕР 1
A16: № | B16: ФИ Клиента | C16: Регион | D16: Телефон | E16: Цена курса (сом) | F16: Статус оплаты | G16: Дата след. оплаты | H16: Остаток (сом) | I16: Комментарий
A38: РЕЕСТР ЛИДОВ - МЕНЕДЖЕР 1
A40: № | J40: Дата платежа | K40: Комментарий
A41: 1
A42: 2
A43: 3
A44: 4
A45: 5

Sheet Mgr_2
A1: 📈 ЕЖЕДНЕВНЫЙ ОТЧЕТ - МЕНЕДЖЕР 2
A2: ПОКАЗАТЕЛИ ЭФФЕКТИВНОСТИ ПО ДНЯМ МЕСЯЦА
A3: МЕТРИКА / ДАТА | B3: 01 | C3: 02 | D3: 03 | E3: 04 | F3: 05 | G3: 06 | H3: 07 | I3: 08 | J3: 09 | K3: 10 | L3: 11 | M3: 12 | N3: 13 | O3: 14 | P3: 15 | Q3: 16 | R3: 17 | S3: 18 | T3: 19 | U3: 20 | V3: 21 | W3: 22 | X3: 23 | Y3: 24 | Z3: 25 | AA3: 26 | AB3: 27 | AC3: 28 | AD3: 29 | AE3: 30 | AF3: 31 | AG3: ИТОГО
A4: Лиды | AG4: =SUM(B4:AF4)
A5: Обработка | AG5: =SUM(B5:AF5)
A6: Не дозвон | AG6: =SUM(B6:AF6)
A7: Ожидание | AG7: =SUM(B7:AF7)
A8: Отказ | AG8: =SUM(B8:AF8)
A9: Продажа | AG9: =SUM(B9:AF9)
A10: Выручка (сом) | AG10: =SUM(B10:AF10)
A11: Конверсия % | AG11: =IF(AG4=0,0,AG9/AG4*100)
A12: Остаток (сом) | AG12: =SUM(B12:AF12)
A15: 📋 РЕЕСТР КЛИЕНТОВ - МЕНЕДЖЕР 2
A16: № | B16: ФИ Клиента | C16: Регион | D16: Телефон | E16: Цена курса (сом) | F16: Статус оплаты | G16: Дата след. оплаты | H16: Остаток (сом) | I16: Комментарий
A38: РЕЕСТР ЛИДОВ - МЕНЕДЖЕР 2
A40: № | J40: Дата платежа | K40: Комментарий
A41: 1
A42: 2
A43: 3
A44: 4
A45: 5

Sheet Mgr_3
A1: 📈 ЕЖЕДНЕВНЫЙ ОТЧЕТ - МЕНЕДЖЕР 3
A2: ПОКАЗАТЕЛИ ЭФФЕКТИВНОСТИ ПО ДНЯМ МЕСЯЦА
A3: МЕТРИКА / ДАТА | B3: 01 | C3: 02 | D3: 03 | E3: 04 | F3: 05 | G3: 06 | H3: 07 | I3: 08 | J3: 09 | K3: 10 | L3: 11 | M3: 12 | N3: 13 | O3: 14 | P3: 15 | Q3: 16 | R3: 17 | S3: 18 | T3: 19 | U3: 20 | V3: 21 | W3: 22 | X3: 23 | Y3: 24 | Z3: 25 | AA3: 26 | AB3: 27 | AC3: 28 | AD3: 29 | AE3: 30 | AF3: 31 | AG3: ИТОГО
A4: Лиды | AG4: =SUM(B4:AF4)
A5: Обработка | AG5: =SUM(B5:AF5)
A6: Не дозвон | AG6: =SUM(B6:AF6)
A7: Ожидание | AG7: =SUM(B7:AF7)
A8: Отказ | AG8: =SUM(B8:AF8)
A9: Продажа | AG9: =SUM(B9:AF9)
A10: Выручка (сом) | AG10: =SUM(B10:AF10)
A11: Конверсия % | AG11: =IF(AG4=0,0,AG9/AG4*100)
A12: Остаток (сом) | AG12: =SUM(B12:AF12)
A15: 📋 РЕЕСТР КЛИЕНТОВ - МЕНЕДЖЕР 3
A16: № | B16: ФИ Клиента | C16: Регион | D16: Телефон | E16: Цена курса (сом) | F16: Статус оплаты | G16: Дата след. оплаты | H16: Остаток (сом) | I16: Комментарий
A38: РЕЕСТР ЛИДОВ - МЕНЕДЖЕР 3
A40: № | J40: Дата платежа | K40: Комментарий
A41: 1
A42: 2
A43: 3
A44: 4
A45: 5

Sheet Mgr_4
A1: 📈 ЕЖЕДНЕВНЫЙ ОТЧЕТ - МЕНЕДЖЕР 4
A2: ПОКАЗАТЕЛИ ЭФФЕКТИВНОСТИ ПО ДНЯМ МЕСЯЦА
A3: МЕТРИКА / ДАТА | B3: 01 | C3: 02 | D3: 03 | E3: 04 | F3: 05 | G3: 06 | H3: 07 | I3: 08 | J3: 09 | K3: 10 | L3: 11 | M3: 12 | N3: 13 | O3: 14 | P3: 15 | Q3: 16 | R3: 17 | S3: 18 | T3: 19 | U3: 20 | V3: 21 | W3: 22 | X3: 23 | Y3: 24 | Z3: 25 | AA3: 26 | AB3: 27 | AC3: 28 | AD3: 29 | AE3: 30 | AF3: 31 | AG3: ИТОГО
A4: Лиды | AG4: =SUM(B4:AF4)
A5: Обработка | AG5: =SUM(B5:AF5)
A6: Не дозвон | AG6: =SUM(B6:AF6)
A7: Ожидание | AG7: =SUM(B7:AF7)
A8: Отказ | AG8: =SUM(B8:AF8)
A9: Продажа | AG9: =SUM(B9:AF9)
A10: Выручка (сом) | AG10: =SUM(B10:AF10)
A11: Конверсия % | AG11: =IF(AG4=0,0,AG9/AG4*100)
A12: Остаток (сом) | AG12: =SUM(B12:AF12)
A15: 📋 РЕЕСТР КЛИЕНТОВ - МЕНЕДЖЕР 4
A16: № | B16: ФИ Клиента | C16: Регион | D16: Телефон | E16: Цена курса (сом) | F16: Статус оплаты | G16: Дата след. оплаты | H16: Остаток (сом) | I16: Комментарий
A38: РЕЕСТР ЛИДОВ - МЕНЕДЖЕР 4
A40: № | J40: Дата платежа | K40: Комментарий
A41: 1
A42: 2
A43: 3
A44: 4
A45: 5

Sheet Mgr_5
A1: 📈 ЕЖЕДНЕВНЫЙ ОТЧЕТ - МЕНЕДЖЕР 5
A2: ПОКАЗАТЕЛИ ЭФФЕКТИВНОСТИ ПО ДНЯМ МЕСЯЦА
A3: МЕТРИКА / ДАТА | B3: 01 | C3: 02 | D3: 03 | E3: 04 | F3: 05 | G3: 06 | H3: 07 | I3: 08 | J3: 09 | K3: 10 | L3: 11 | M3: 12 | N3: 13 | O3: 14 | P3: 15 | Q3: 16 | R3: 17 | S3: 18 | T3: 19 | U3: 20 | V3: 21 | W3: 22 | X3: 23 | Y3: 24 | Z3: 25 | AA3: 26 | AB3: 27 | AC3: 28 | AD3: 29 | AE3: 30 | AF3: 31 | AG3: ИТОГО
A4: Лиды | AG4: =SUM(B4:AF4)
A5: Обработка | AG5: =SUM(B5:AF5)
A6: Не дозвон | AG6: =SUM(B6:AF6)
A7: Ожидание | AG7: =SUM(B7:AF7)
A8: Отказ | AG8: =SUM(B8:AF8)
A9: Продажа | AG9: =SUM(B9:AF9)
A10: Выручка (сом) | AG10: =SUM(B10:AF10)
A11: Конверсия % | AG11: =IF(AG4=0,0,AG9/AG4*100)
A12: Остаток (сом) | AG12: =SUM(B12:AF12)
A15: 📋 РЕЕСТР КЛИЕНТОВ - МЕНЕДЖЕР 5
A16: № | B16: ФИ Клиента | C16: Регион | D16: Телефон | E16: Цена курса (сом) | F16: Статус оплаты | G16: Дата след. оплаты | H16: Остаток (сом) | I16: Комментарий
A38: РЕЕСТР ЛИДОВ - МЕНЕДЖЕР 5
A40: № | J40: Дата платежа | K40: Комментарий
A41: 1
A42: 2
A43: 3
A44: 4
A45: 5

Sheet Mgr_6
A1: 📈 ЕЖЕДНЕВНЫЙ ОТЧЕТ - МЕНЕДЖЕР 6
A2: ПОКАЗАТЕЛИ ЭФФЕКТИВНОСТИ ПО ДНЯМ МЕСЯЦА
A3: МЕТРИКА / ДАТА | B3: 01 | C3: 02 | D3: 03 | E3: 04 | F3: 05 | G3: 06 | H3: 07 | I3: 08 | J3: 09 | K3: 10 | L3: 11 | M3: 12 | N3: 13 | O3: 14 | P3: 15 | Q3: 16 | R3: 17 | S3: 18 | T3: 19 | U3: 20 | V3: 21 | W3: 22 | X3: 23 | Y3: 24 | Z3: 25 | AA3: 26 | AB3: 27 | AC3: 28 | AD3: 29 | AE3: 30 | AF3: 31 | AG3: ИТОГО
A4: Лиды | AG4: =SUM(B4:AF4)
A5: Обработка | AG5: =SUM(B5:AF5)
A6: Не дозвон | AG6: =SUM(B6:AF6)
A7: Ожидание | AG7: =SUM(B7:AF7)
A8: Отказ | AG8: =SUM(B8:AF8)
A9: Продажа | AG9: =SUM(B9:AF9)
A10: Выручка (сом) | AG10: =SUM(B10:AF10)
A11: Конверсия % | AG11: =IF(AG4=0,0,AG9/AG4*100)
A12: Остаток (сом) | AG12: =SUM(B12:AF12)
A15: 📋 РЕЕСТР КЛИЕНТОВ - МЕНЕДЖЕР 6
A16: № | B16: ФИ Клиента | C16: Регион | D16: Телефон | E16: Цена курса (сом) | F16: Статус оплаты | G16: Дата след. оплаты | H16: Остаток (сом) | I16: Комментарий
A38: РЕЕСТР ЛИДОВ - МЕНЕДЖЕР 6
A40: № | J40: Дата платежа | K40: Комментарий
A41: 1
A42: 2
A43: 3
A44: 4
A45: 5

Sheet Mgr_7
A1: 📈 ЕЖЕДНЕВНЫЙ ОТЧЕТ - МЕНЕДЖЕР 7
A2: ПОКАЗАТЕЛИ ЭФФЕКТИВНОСТИ ПО ДНЯМ МЕСЯЦА
A3: МЕТРИКА / ДАТА | B3: 01 | C3: 02 | D3: 03 | E3: 04 | F3: 05 | G3: 06 | H3: 07 | I3: 08 | J3: 09 | K3: 10 | L3: 11 | M3: 12 | N3: 13 | O3: 14 | P3: 15 | Q3: 16 | R3: 17 | S3: 18 | T3: 19 | U3: 20 | V3: 21 | W3: 22 | X3: 23 | Y3: 24 | Z3: 25 | AA3: 26 | AB3: 27 | AC3: 28 | AD3: 29 | AE3: 30 | AF3: 31 | AG3: ИТОГО
A4: Лиды | AG4: =SUM(B4:AF4)
A5: Обработка | AG5: =SUM(B5:AF5)
A6: Не дозвон | AG6: =SUM(B6:AF6)
A7: Ожидание | AG7: =SUM(B7:AF7)
A8: Отказ | AG8: =SUM(B8:AF8)
A9: Продажа | AG9: =SUM(B9:AF9)
A10: Выручка (сом) | AG10: =SUM(B10:AF10)
A11: Конверсия % | AG11: =IF(AG4=0,0,AG9/AG4*100)
A12: Остаток (сом) | AG12: =SUM(B12:AF12)
A15: 📋 РЕЕСТР КЛИЕНТОВ - МЕНЕДЖЕР 7
A16: № | B16: ФИ Клиента | C16: Регион | D16: Телефон | E16: Цена курса (сом) | F16: Статус оплаты | G16: Дата след. оплаты | H16: Остаток (сом) | I16: Комментарий
A38: РЕЕСТР ЛИДОВ - МЕНЕДЖЕР 7
A40: № | J40: Дата платежа | K40: Комментарий
A41: 1
A42: 2
A43: 3
A44: 4
A45: 5

Sheet Mgr_8
A1: 📈 ЕЖЕДНЕВНЫЙ ОТЧЕТ - МЕНЕДЖЕР 8
A2: ПОКАЗАТЕЛИ ЭФФЕКТИВНОСТИ ПО ДНЯМ МЕСЯЦА
A3: МЕТРИКА / ДАТА | B3: 01 | C3: 02 | D3: 03 | E3: 04 | F3: 05 | G3: 06 | H3: 07 | I3: 08 | J3: 09 | K3: 10 | L3: 11 | M3: 12 | N3: 13 | O3: 14 | P3: 15 | Q3: 16 | R3: 17 | S3: 18 | T3: 19 | U3: 20 | V3: 21 | W3: 22 | X3: 23 | Y3: 24 | Z3: 25 | AA3: 26 | AB3: 27 | AC3: 28 | AD3: 29 | AE3: 30 | AF3: 31 | AG3: ИТОГО
A4: Лиды | AG4: =SUM(B4:AF4)
A5: Обработка | AG5: =SUM(B5:AF5)
A6: Не дозвон | AG6: =SUM(B6:AF6)
A7: Ожидание | AG7: =SUM(B7:AF7)
A8: Отказ | AG8: =SUM(B8:AF8)
A9: Продажа | AG9: =SUM(B9:AF9)
A10: Выручка (сом) | AG10: =SUM(B10:AF10)
A11: Конверсия % | AG11: =IF(AG4=0,0,AG9/AG4*100)
A12: Остаток (сом) | AG12: =SUM(B12:AF12)
A15: 📋 РЕЕСТР КЛИЕНТОВ - МЕНЕДЖЕР 8
A16: № | B16: ФИ Клиента | C16: Регион | D16: Телефон | E16: Цена курса (сом) | F16: Статус оплаты | G16: Дата след. оплаты | H16: Остаток (сом) | I16: Комментарий
A38: РЕЕСТР ЛИДОВ - МЕНЕДЖЕР 8
A40: № | J40: Дата платежа | K40: Комментарий
A41: 1
A42: 2
A43: 3
A44: 4
A45: 5

Sheet Mgr_9
A1: 📈 ЕЖЕДНЕВНЫЙ ОТЧЕТ - МЕНЕДЖЕР 9
A2: ПОКАЗАТЕЛИ ЭФФЕКТИВНОСТИ ПО ДНЯМ МЕСЯЦА
A3: МЕТРИКА / ДАТА | B3: 01 | C3: 02 | D3: 03 | E3: 04 | F3: 05 | G3: 06 | H3: 07 | I3: 08 | J3: 09 | K3: 10 | L3: 11 | M3: 12 | N3: 13 | O3: 14 | P3: 15 | Q3: 16 | R3: 17 | S3: 18 | T3: 19 | U3: 20 | V3: 21 | W3: 22 | X3: 23 | Y3: 24 | Z3: 25 | AA3: 26 | AB3: 27 | AC3: 28 | AD3: 29 | AE3: 30 | AF3: 31 | AG3: ИТОГО
A4: Лиды | AG4: =SUM(B4:AF4)
A5: Обработка | AG5: =SUM(B5:AF5)
A6: Не дозвон | AG6: =SUM(B6:AF6)
A7: Ожидание | AG7: =SUM(B7:AF7)
A8: Отказ | AG8: =SUM(B8:AF8)
A9: Продажа | AG9: =SUM(B9:AF9)
A10: Выручка (сом) | AG10: =SUM(B10:AF10)
A11: Конверсия % | AG11: =IF(AG4=0,0,AG9/AG4*100)
A12: Остаток (сом) | AG12: =SUM(B12:AF12)
A15: 📋 РЕЕСТР КЛИЕНТОВ - МЕНЕДЖЕР 9
A16: № | B16: ФИ Клиента | C16: Регион | D16: Телефон | E16: Цена курса (сом) | F16: Статус оплаты | G16: Дата след. оплаты | H16: Остаток (сом) | I16: Комментарий
A38: РЕЕСТР ЛИДОВ - МЕНЕДЖЕР 9
A40: № | J40: Дата платежа | K40: Комментарий
A41: 1
A42: 2
A43: 3
A44: 4
A45: 5

Sheet Mgr_10
A1: 📈 ЕЖЕДНЕВНЫЙ ОТЧЕТ - МЕНЕДЖЕР 10
A2: ПОКАЗАТЕЛИ ЭФФЕКТИВНОСТИ ПО ДНЯМ МЕСЯЦА
A3: МЕТРИКА / ДАТА | B3: 01 | C3: 02 | D3: 03 | E3: 04 | F3: 05 | G3: 06 | H3: 07 | I3: 08 | J3: 09 | K3: 10 | L3: 11 | M3: 12 | N3: 13 | O3: 14 | P3: 15 | Q3: 16 | R3: 17 | S3: 18 | T3: 19 | U3: 20 | V3: 21 | W3: 22 | X3: 23 | Y3: 24 | Z3: 25 | AA3: 26 | AB3: 27 | AC3: 28 | AD3: 29 | AE3: 30 | AF3: 31 | AG3: ИТОГО
A4: Лиды | AG4: =SUM(B4:AF4)
A5: Обработка | AG5: =SUM(B5:AF5)
A6: Не дозвон | AG6: =SUM(B6:AF6)
A7: Ожидание | AG7: =SUM(B7:AF7)
A8: Отказ | AG8: =SUM(B8:AF8)
A9: Продажа | AG9: =SUM(B9:AF9)
A10: Выручка (сом) | AG10: =SUM(B10:AF10)
A11: Конверсия % | AG11: =IF(AG4=0,0,AG9/AG4*100)
A12: Остаток (сом) | AG12: =SUM(B12:AF12)
A15: 📋 РЕЕСТР КЛИЕНТОВ - МЕНЕДЖЕР 10
A16: № | B16: ФИ Клиента | C16: Регион | D16: Телефон | E16: Цена курса (сом) | F16: Статус оплаты | G16: Дата след. оплаты | H16: Остаток (сом) | I16: Комментарий
A38: РЕЕСТР ЛИДОВ - МЕНЕДЖЕР 10
A40: № | J40: Дата платежа | K40: Комментарий
A41: 1
A42: 2
A43: 3
A44: 4
A45: 5

Sheet Mgr_11
A1: 📈 ЕЖЕДНЕВНЫЙ ОТЧЕТ - МЕНЕДЖЕР 11
A2: ПОКАЗАТЕЛИ ЭФФЕКТИВНОСТИ ПО ДНЯМ МЕСЯЦА
A3: МЕТРИКА / ДАТА | B3: 01 | C3: 02 | D3: 03 | E3: 04 | F3: 05 | G3: 06 | H3: 07 | I3: 08 | J3: 09 | K3: 10 | L3: 11 | M3: 12 | N3: 13 | O3: 14 | P3: 15 | Q3: 16 | R3: 17 | S3: 18 | T3: 19 | U3: 20 | V3: 21 | W3: 22 | X3: 23 | Y3: 24 | Z3: 25 | AA3: 26 | AB3: 27 | AC3: 28 | AD3: 29 | AE3: 30 | AF3: 31 | AG3: ИТОГО
A4: Лиды | AG4: =SUM(B4:AF4)
A5: Обработка | AG5: =SUM(B5:AF5)
A6: Не дозвон | AG6: =SUM(B6:AF6)
A7: Ожидание | AG7: =SUM(B7:AF7)
A8: Отказ | AG8: =SUM(B8:AF8)
A9: Продажа | AG9: =SUM(B9:AF9)
A10: Выручка (сом) | AG10: =SUM(B10:AF10)
A11: Конверсия % | AG11: =IF(AG4=0,0,AG9/AG4*100)
A12: Остаток (сом) | AG12: =SUM(B12:AF12)
A15: 📋 РЕЕСТР КЛИЕНТОВ - МЕНЕДЖЕР 11
A16: № | B16: ФИ Клиента | C16: Регион | D16: Телефон | E16: Цена курса (сом) | F16: Статус оплаты | G16: Дата след. оплаты | H16: Остаток (сом) | I16: Комментарий
A38: РЕЕСТР ЛИДОВ - МЕНЕДЖЕР 11
A40: № | J40: Дата платежа | K40: Комментарий
A41: 1
A42: 2
A43: 3
A44: 4
A45: 5

Sheet Mgr_12
A1: 📈 ЕЖЕДНЕВНЫЙ ОТЧЕТ - МЕНЕДЖЕР 12
A2: ПОКАЗАТЕЛИ ЭФФЕКТИВНОСТИ ПО ДНЯМ МЕСЯЦА
A3: МЕТРИКА / ДАТА | B3: 01 | C3: 02 | D3: 03 | E3: 04 | F3: 05 | G3: 06 | H3: 07 | I3: 08 | J3: 09 | K3: 10 | L3: 11 | M3: 12 | N3: 13 | O3: 14 | P3: 15 | Q3: 16 | R3: 17 | S3: 18 | T3: 19 | U3: 20 | V3: 21 | W3: 22 | X3: 23 | Y3: 24 | Z3: 25 | AA3: 26 | AB3: 27 | AC3: 28 | AD3: 29 | AE3: 30 | AF3: 31 | AG3: ИТОГО
A4: Лиды | AG4: =SUM(B4:AF4)
A5: Обработка | AG5: =SUM(B5:AF5)
A6: Не дозвон | AG6: =SUM(B6:AF6)
A7: Ожидание | AG7: =SUM(B7:AF7)
A8: Отказ | AG8: =SUM(B8:AF8)
A9: Продажа | AG9: =SUM(B9:AF9)
A10: Выручка (сом) | AG10: =SUM(B10:AF10)
A11: Конверсия % | AG11: =IF(AG4=0,0,AG9/AG4*100)
A12: Остаток (сом) | AG12: =SUM(B12:AF12)
A15: 📋 РЕЕСТР КЛИЕНТОВ - МЕНЕДЖЕР 12
A16: № | B16: ФИ Клиента | C16: Регион | D16: Телефон | E16: Цена курса (сом) | F16: Статус оплаты | G16: Дата след. оплаты | H16: Остаток (сом) | I16: Комментарий
A38: РЕЕСТР ЛИДОВ - МЕНЕДЖЕР 12
A40: № | J40: Дата платежа | K40: Комментарий
A41: 1
A42: 2
A43: 3
A44: 4
A45: 5

Sheet Mgr_13
A1: 📈 ЕЖЕДНЕВНЫЙ ОТЧЕТ - МЕНЕДЖЕР 13
A2: ПОКАЗАТЕЛИ ЭФФЕКТИВНОСТИ ПО ДНЯМ МЕСЯЦА
A3: МЕТРИКА / ДАТА | B3: 01 | C3: 02 | D3: 03 | E3: 04 | F3: 05 | G3: 06 | H3: 07 | I3: 08 | J3: 09 | K3: 10 | L3: 11 | M3: 12 | N3: 13 | O3: 14 | P3: 15 | Q3: 16 | R3: 17 | S3: 18 | T3: 19 | U3: 20 | V3: 21 | W3: 22 | X3: 23 | Y3: 24 | Z3: 25 | AA3: 26 | AB3: 27 | AC3: 28 | AD3: 29 | AE3: 30 | AF3: 31 | AG3: ИТОГО
A4: Лиды | AG4: =SUM(B4:AF4)
A5: Обработка | AG5: =SUM(B5:AF5)
A6: Не дозвон | AG6: =SUM(B6:AF6)
A7: Ожидание | AG7: =SUM(B7:AF7)
A8: Отказ | AG8: =SUM(B8:AF8)
A9: Продажа | AG9: =SUM(B9:AF9)
A10: Выручка (сом) | AG10: =SUM(B10:AF10)
A11: Конверсия % | AG11: =IF(AG4=0,0,AG9/AG4*100)
A12: Остаток (сом) | AG12: =SUM(B12:AF12)
A15: 📋 РЕЕСТР КЛИЕНТОВ - МЕНЕДЖЕР 13
A16: № | B16: ФИ Клиента | C16: Регион | D16: Телефон | E16: Цена курса (сом) | F16: Статус оплаты | G16: Дата след. оплаты | H16: Остаток (сом) | I16: Комментарий
A38: РЕЕСТР ЛИДОВ - МЕНЕДЖЕР 13
A40: № | J40: Дата платежа | K40: Комментарий
A41: 1
A42: 2
A43: 3
A44: 4
A45: 5

Sheet Mgr_14
A1: 📈 ЕЖЕДНЕВНЫЙ ОТЧЕТ - МЕНЕДЖЕР 14
A2: ПОКАЗАТЕЛИ ЭФФЕКТИВНОСТИ ПО ДНЯМ МЕСЯЦА
A3: МЕТРИКА / ДАТА | B3: 01 | C3: 02 | D3: 03 | E3: 04 | F3: 05 | G3: 06 | H3: 07 | I3: 08 | J3: 09 | K3: 10 | L3: 11 | M3: 12 | N3: 13 | O3: 14 | P3: 15 | Q3: 16 | R3: 17 | S3: 18 | T3: 19 | U3: 20 | V3: 21 | W3: 22 | X3: 23 | Y3: 24 | Z3: 25 | AA3: 26 | AB3: 27 | AC3: 28 | AD3: 29 | AE3: 30 | AF3: 31 | AG3: ИТОГО
A4: Лиды | AG4: =SUM(B4:AF4)
A5: Обработка | AG5: =SUM(B5:AF5)
A6: Не дозвон | AG6: =SUM(B6:AF6)
A7: Ожидание | AG7: =SUM(B7:AF7)
A8: Отказ | AG8: =SUM(B8:AF8)
A9: Продажа | AG9: =SUM(B9:AF9)
A10: Выручка (сом) | AG10: =SUM(B10:AF10)
A11: Конверсия % | AG11: =IF(AG4=0,0,AG9/AG4*100)
A12: Остаток (сом) | AG12: =SUM(B12:AF12)
A15: 📋 РЕЕСТР КЛИЕНТОВ - МЕНЕДЖЕР 14
A16: № | B16: ФИ Клиента | C16: Регион | D16: Телефон | E16: Цена курса (сом) | F16: Статус оплаты | G16: Дата след. оплаты | H16: Остаток (сом) | I16: Комментарий
A38: РЕЕСТР ЛИДОВ - МЕНЕДЖЕР 14
A40: № | J40: Дата платежа | K40: Комментарий
A41: 1
A42: 2
A43: 3
A44: 4
A45: 5

Sheet Mgr_15
A1: 📈 ЕЖЕДНЕВНЫЙ ОТЧЕТ - МЕНЕДЖЕР 15
A2: ПОКАЗАТЕЛИ ЭФФЕКТИВНОСТИ ПО ДНЯМ МЕСЯЦА
A3: МЕТРИКА / ДАТА | B3: 01 | C3: 02 | D3: 03 | E3: 04 | F3: 05 | G3: 06 | H3: 07 | I3: 08 | J3: 09 | K3: 10 | L3: 11 | M3: 12 | N3: 13 | O3: 14 | P3: 15 | Q3: 16 | R3: 17 | S3: 18 | T3: 19 | U3: 20 | V3: 21 | W3: 22 | X3: 23 | Y3: 24 | Z3: 25 | AA3: 26 | AB3: 27 | AC3: 28 | AD3: 29 | AE3: 30 | AF3: 31 | AG3: ИТОГО
A4: Лиды | AG4: =SUM(B4:AF4)
A5: Обработка | AG5: =SUM(B5:AF5)
A6: Не дозвон | AG6: =SUM(B6:AF6)
A7: Ожидание | AG7: =SUM(B7:AF7)
A8: Отказ | AG8: =SUM(B8:AF8)
A9: Продажа | AG9: =SUM(B9:AF9)
A10: Выручка (сом) | AG10: =SUM(B10:AF10)
A11: Конверсия % | AG11: =IF(AG4=0,0,AG9/AG4*100)
A12: Остаток (сом) | AG12: =SUM(B12:AF12)
A15: 📋 РЕЕСТР КЛИЕНТОВ - МЕНЕДЖЕР 15
A16: № | B16: ФИ Клиента | C16: Регион | D16: Телефон | E16: Цена курса (сом) | F16: Статус оплаты | G16: Дата след. оплаты | H16: Остаток (сом) | I16: Комментарий
A38: РЕЕСТР ЛИДОВ - МЕНЕДЖЕР 15
A40: № | J40: Дата платежа | K40: Комментарий
A41: 1
A42: 2
A43: 3
A44: 4
A45: 5

Sheet Mgr_16
A1: 📈 ЕЖЕДНЕВНЫЙ ОТЧЕТ - МЕНЕДЖЕР 16
A2: ПОКАЗАТЕЛИ ЭФФЕКТИВНОСТИ ПО ДНЯМ МЕСЯЦА
A3: МЕТРИКА / ДАТА | B3: 01 | C3: 02 | D3: 03 | E3: 04 | F3: 05 | G3: 06 | H3: 07 | I3: 08 | J3: 09 | K3: 10 | L3: 11 | M3: 12 | N3: 13 | O3: 14 | P3: 15 | Q3: 16 | R3: 17 | S3: 18 | T3: 19 | U3: 20 | V3: 21 | W3: 22 | X3: 23 | Y3: 24 | Z3: 25 | AA3: 26 | AB3: 27 | AC3: 28 | AD3: 29 | AE3: 30 | AF3: 31 | AG3: ИТОГО
A4: Лиды | AG4: =SUM(B4:AF4)
A5: Обработка | AG5: =SUM(B5:AF5)
A6: Не дозвон | AG6: =SUM(B6:AF6)
A7: Ожидание | AG7: =SUM(B7:AF7)
A8: Отказ | AG8: =SUM(B8:AF8)
A9: Продажа | AG9: =SUM(B9:AF9)
A10: Выручка (сом) | AG10: =SUM(B10:AF10)
A11: Конверсия % | AG11: =IF(AG4=0,0,AG9/AG4*100)
A12: Остаток (сом) | AG12: =SUM(B12:AF12)
A15: 📋 РЕЕСТР КЛИЕНТОВ - МЕНЕДЖЕР 16
A16: № | B16: ФИ Клиента | C16: Регион | D16: Телефон | E16: Цена курса (сом) | F16: Статус оплаты | G16: Дата след. оплаты | H16: Остаток (сом) | I16: Комментарий
A38: РЕЕСТР ЛИДОВ - МЕНЕДЖЕР 16
A40: № | J40: Дата платежа | K40: Комментарий
A41: 1
A42: 2
A43: 3
A44: 4
A45: 5

Sheet Mgr_17
A1: 📈 ЕЖЕДНЕВНЫЙ ОТЧЕТ - МЕНЕДЖЕР 17
A2: ПОКАЗАТЕЛИ ЭФФЕКТИВНОСТИ ПО ДНЯМ МЕСЯЦА
A3: МЕТРИКА / ДАТА | B3: 01 | C3: 02 | D3: 03 | E3: 04 | F3: 05 | G3: 06 | H3: 07 | I3: 08 | J3: 09 | K3: 10 | L3: 11 | M3: 12 | N3: 13 | O3: 14 | P3: 15 | Q3: 16 | R3: 17 | S3: 18 | T3: 19 | U3: 20 | V3: 21 | W3: 22 | X3: 23 | Y3: 24 | Z3: 25 | AA3: 26 | AB3: 27 | AC3: 28 | AD3: 29 | AE3: 30 | AF3: 31 | AG3: ИТОГО
A4: Лиды | AG4: =SUM(B4:AF4)
A5: Обработка | AG5: =SUM(B5:AF5)
A6: Не дозвон | AG6: =SUM(B6:AF6)
A7: Ожидание | AG7: =SUM(B7:AF7)
A8: Отказ | AG8: =SUM(B8:AF8)
A9: Продажа | AG9: =SUM(B9:AF9)
A10: Выручка (сом) | AG10: =SUM(B10:AF10)
A11: Конверсия % | AG11: =IF(AG4=0,0,AG9/AG4*100)
A12: Остаток (сом) | AG12: =SUM(B12:AF12)
A15: 📋 РЕЕСТР КЛИЕНТОВ - МЕНЕДЖЕР 17
A16: № | B16: ФИ Клиента | C16: Регион | D16: Телефон | E16: Цена курса (сом) | F16: Статус оплаты | G16: Дата след. оплаты | H16: Остаток (сом) | I16: Комментарий
A38: РЕЕСТР ЛИДОВ - МЕНЕДЖЕР 17
A40: № | J40: Дата платежа | K40: Комментарий
A41: 1
A42: 2
A43: 3
A44: 4
A45: 5

Sheet Mgr_18
A1: 📈 ЕЖЕДНЕВНЫЙ ОТЧЕТ - МЕНЕДЖЕР 18
A2: ПОКАЗАТЕЛИ ЭФФЕКТИВНОСТИ ПО ДНЯМ МЕСЯЦА
A3: МЕТРИКА / ДАТА | B3: 01 | C3: 02 | D3: 03 | E3: 04 | F3: 05 | G3: 06 | H3: 07 | I3: 08 | J3: 09 | K3: 10 | L3: 11 | M3: 12 | N3: 13 | O3: 14 | P3: 15 | Q3: 16 | R3: 17 | S3: 18 | T3: 19 | U3: 20 | V3: 21 | W3: 22 | X3: 23 | Y3: 24 | Z3: 25 | AA3: 26 | AB3: 27 | AC3: 28 | AD3: 29 | AE3: 30 | AF3: 31 | AG3: ИТОГО
A4: Лиды | AG4: =SUM(B4:AF4)
A5: Обработка | AG5: =SUM(B5:AF5)
A6: Не дозвон | AG6: =SUM(B6:AF6)
A7: Ожидание | AG7: =SUM(B7:AF7)
A8: Отказ | AG8: =SUM(B8:AF8)
A9: Продажа | AG9: =SUM(B9:AF9)
A10: Выручка (сом) | AG10: =SUM(B10:AF10)
A11: Конверсия % | AG11: =IF(AG4=0,0,AG9/AG4*100)
A12: Остаток (сом) | AG12: =SUM(B12:AF12)
A15: 📋 РЕЕСТР КЛИЕНТОВ - МЕНЕДЖЕР 18
A16: № | B16: ФИ Клиента | C16: Регион | D16: Телефон | E16: Цена курса (сом) | F16: Статус оплаты | G16: Дата след. оплаты | H16: Остаток (сом) | I16: Комментарий
A38: РЕЕСТР ЛИДОВ - МЕНЕДЖЕР 18
A40: № | J40: Дата платежа | K40: Комментарий
A41: 1
A42: 2
A43: 3
A44: 4
A45: 5

Sheet Mgr_19
A1: 📈 ЕЖЕДНЕВНЫЙ ОТЧЕТ - МЕНЕДЖЕР 19
A2: ПОКАЗАТЕЛИ ЭФФЕКТИВНОСТИ ПО ДНЯМ МЕСЯЦА
A3: МЕТРИКА / ДАТА | B3: 01 | C3: 02 | D3: 03 | E3: 04 | F3: 05 | G3: 06 | H3: 07 | I3: 08 | J3: 09 | K3: 10 | L3: 11 | M3: 12 | N3: 13 | O3: 14 | P3: 15 | Q3: 16 | R3: 17 | S3: 18 | T3: 19 | U3: 20 | V3: 21 | W3: 22 | X3: 23 | Y3: 24 | Z3: 25 | AA3: 26 | AB3: 27 | AC3: 28 | AD3: 29 | AE3: 30 | AF3: 31 | AG3: ИТОГО
A4: Лиды | AG4: =SUM(B4:AF4)
A5: Обработка | AG5: =SUM(B5:AF5)
A6: Не дозвон | AG6: =SUM(B6:AF6)
A7: Ожидание | AG7: =SUM(B7:AF7)
A8: Отказ | AG8: =SUM(B8:AF8)
A9: Продажа | AG9: =SUM(B9:AF9)
A10: Выручка (сом) | AG10: =SUM(B10:AF10)
A11: Конверсия % | AG11: =IF(AG4=0,0,AG9/AG4*100)
A12: Остаток (сом) | AG12: =SUM(B12:AF12)
A15: 📋 РЕЕСТР КЛИЕНТОВ - МЕНЕДЖЕР 19
A16: № | B16: ФИ Клиента | C16: Регион | D16: Телефон | E16: Цена курса (сом) | F16: Статус оплаты | G16: Дата след. оплаты | H16: Остаток (сом) | I16: Комментарий
A38: РЕЕСТР ЛИДОВ - МЕНЕДЖЕР 19
A40: № | J40: Дата платежа | K40: Комментарий
A41: 1
A42: 2
A43: 3
A44: 4
A45: 5

Sheet Mgr_20
A1: 📈 ЕЖЕДНЕВНЫЙ ОТЧЕТ - МЕНЕДЖЕР 20
A2: ПОКАЗАТЕЛИ ЭФФЕКТИВНОСТИ ПО ДНЯМ МЕСЯЦА
A3: МЕТРИКА / ДАТА | B3: 01 | C3: 02 | D3: 03 | E3: 04 | F3: 05 | G3: 06 | H3: 07 | I3: 08 | J3: 09 | K3: 10 | L3: 11 | M3: 12 | N3: 13 | O3: 14 | P3: 15 | Q3: 16 | R3: 17 | S3: 18 | T3: 19 | U3: 20 | V3: 21 | W3: 22 | X3: 23 | Y3: 24 | Z3: 25 | AA3: 26 | AB3: 27 | AC3: 28 | AD3: 29 | AE3: 30 | AF3: 31 | AG3: ИТОГО
A4: Лиды | AG4: =SUM(B4:AF4)
A5: Обработка | AG5: =SUM(B5:AF5)
A6: Не дозвон | AG6: =SUM(B6:AF6)
A7: Ожидание | AG7: =SUM(B7:AF7)
A8: Отказ | AG8: =SUM(B8:AF8)
A9: Продажа | AG9: =SUM(B9:AF9)
A10: Выручка (сом) | AG10: =SUM(B10:AF10)
A11: Конверсия % | AG11: =IF(AG4=0,0,AG9/AG4*100)
A12: Остаток (сом) | AG12: =SUM(B12:AF12)
A15: 📋 РЕЕСТР КЛИЕНТОВ - МЕНЕДЖЕР 20
A16: № | B16: ФИ Клиента | C16: Регион | D16: Телефон | E16: Цена курса (сом) | F16: Статус оплаты | G16: Дата след. оплаты | H16: Остаток (сом) | I16: Комментарий
A38: РЕЕСТР ЛИДОВ - МЕНЕДЖЕР 20
A40: № | J40: Дата платежа | K40: Комментарий
A41: 1
A42: 2
A43: 3
A44: 4
A45: 5
